Workbook

Sheet Cómo usar
B2: Del libro diario al estado de flujos de efectivo
B3: Estados Financieros · Sesión 2 · plantilla para completar
B5: Qué hay en este archivo
B6: Dos casos completos, cada uno con sus tres hojas: la situación financiera, el libro diario y el estado de flujos.
B7: Caso 5 — Comercial Los Andes E.I.R.L. (marzo de 2026): 10 asientos.
B8: Caso 6 — Servicios Yanahuara S.A.C. (abril de 2026): 13 asientos, con las tres actividades.
B10: Qué tiene que hacer el alumno — solo dos columnas
B11: 1. En la hoja del DIARIO, en la fila gris de cada asiento, columna «¿Mueve efectivo?»: elegir SÍ o NO en la lista.
B12: Mueve efectivo el asiento que toca 101 Caja, 102 Fondos fijos o 1041 Cuentas corrientes.
B13: Ojo con el asiento de apertura: toca esas cuentas pero no es movimiento del mes, va NO.
B14: 2. Si puso SÍ, en la columna «¿A qué renglón del flujo va?»: elegir el renglón en la lista.
B16: Lo demás se calcula solo
... B26: Versión interactiva: eduardoaeges.github.io/cursos_edu/efe-desde-diario.html

Sheet Caso 5 · Situación
A1: ESTADO DE SITUACIÓN FINANCIERA — COMERCIAL LOS ANDES E.I.R.L.
A2: RUC 20548877231 · Marzo de 2026 · en soles
A4: Código | B4: Cuenta | C4: Al cierre | D4: Al inicio
A5: ACTIVO
A6: 101 | B6: Caja | C6: 3000 | D6: 3000
A7: 1041 | B7: Cuentas corrientes operativas | C7: 49750 | D7: 27000
A8: 1212 | B8: Facturas por cobrar — terceros | C8: 0 | D8: 48000
A9: 40111 | B9: Tributos por recuperar — IGV | C9: 945.76 | D9: 0
A10: 2011 | B10: Mercaderías manufacturadas | C10: 18000 | D10: 18000
A11: 33611 | B11: Equipos de procesamiento de información | C11: 5254.24 | D11: 0
A12: 39133 | B12: Depreciación acumulada | C12: -109.46 | D12: 0
B13: TOTAL ACTIVO | C13: 76840.54 | D13: 96000
A14: PASIVO
A15: 4212 | B15: Facturas emitidas por pagar — terceros | C15: 0 | D15: 21000
A16: 40111 | B16: Tributos por pagar — IGV | C16: 0 | D16: 3100
A17: 4511 | B17: Préstamos de instituciones financieras | C17: 15000 | D17: 0
B18: TOTAL PASIVO | C18: 15000 | D18: 24100
A19: PATRIMONIO
A20: 5011 | B20: Capital — acciones | C20: 70000 | D20: 70000
A21: 5911 | B21: Resultados acumulados | C21: 1900 | D21: 1900
A22: 59 | B22: Resultado del ejercicio | C22: -10059.46 | D22: 0
B23: TOTAL PATRIMONIO | C23: 61840.54 | D23: 71900
B24: TOTAL PASIVO Y PATRIMONIO | C24: 76840.54 | D24: 96000
B26: EFECTIVO Y EQUIVALENTES DE EFECTIVO | C26: 52750 | D26: 30000
B27: VARIACIÓN DEL EFECTIVO EN EL MES | C27: 22750
A29: Las filas en amarillo son el efectivo. Esa variación de S/ 22,750.00 es la que el estado de flujos tiene que explicar, renglón por renglón.

Sheet Caso 5 · Diario
A1: LIBRO DIARIO — COMERCIAL LOS ANDES E.I.R.L.
A2: RUC 20548877231 · Marzo de 2026 · formato 5.1 · completa las columnas G e I
A4: N° | B4: Fecha | C4: Código | D4: Denominación | E4: Debe | F4: Haber | G4: ¿Mueve efectivo? | H4: Importe del flujo | I4: ¿A qué renglón del flujo va?
A5: A-01 · 01/03/2026 · Por el asiento de apertura | H5: =IF($G$5="SÍ",SUMPRODUCT((($C$6:$C$13="101")+($C$6:$C$13="102")+($C$6:$C$13="1041"))*($E$6:$E$13-$F$6:$F$13)),0)
C6: 101 | D6: CAJA | E6: 3000
C7: 1041 | D7: CUENTAS CORRIENTES OPERATIVAS | E7: 27000
C8: 1212 | D8: FACTURAS POR COBRAR EMITIDAS EN CARTERA — TERCEROS | E8: 48000
C9: 2011 | D9: MERCADERÍAS MANUFACTURADAS | E9: 18000
C10: 4212 | D10: FACTURAS EMITIDAS POR PAGAR — TERCEROS | F10: 21000
C11: 40111 | D11: IGV — CUENTA PROPIA | F11: 3100
C12: 5011 | D12: ACCIONES | F12: 70000
C13: 5911 | D13: UTILIDADES ACUMULADAS | F13: 1900
A15: A-02 · 03/03/2026 · Por el cobro de las facturas del mes anterior | H15: =IF($G$15="SÍ",SUMPRODUCT((($C$16:$C$17="101")+($C$16:$C$17="102")+($C$16:$C$17="1041"))*($E$16:$E$17-$F$16:$F$17)),0)
C16: 1041 | D16: CUENTAS CORRIENTES OPERATIVAS | E16: 48000
C17: 1212 | D17: FACTURAS POR COBRAR EMITIDAS EN CARTERA — TERCEROS | F17: 48000
A19: A-03 · 05/03/2026 · Por el pago a los proveedores de mercadería | H19: =IF($G$19="SÍ",SUMPRODUCT((($C$20:$C$21="101")+($C$20:$C$21="102")+($C$20:$C$21="1041"))*($E$20:$E$21-$F$20:$F$21)),0)
C20: 4212 | D20: FACTURAS EMITIDAS POR PAGAR — TERCEROS | E20: 21000
C21: 1041 | D21: CUENTAS CORRIENTES OPERATIVAS | F21: 21000
A23: A-04 · 08/03/2026 · Por la compra de una computadora al contado | H23: =IF($G$23="SÍ",SUMPRODUCT((($C$24:$C$26="101")+($C$24:$C$26="102")+($C$24:$C$26="1041"))*($E$24:$E$26-$F$24:$F$26)),0)
C24: 33611 | D24: EQUIPOS DE PROCESAMIENTO DE INFORMACIÓN — COSTO | E24: 5254.24
C25: 40111 | D25: IGV — CUENTA PROPIA | E25: 945.76
C26: 1041 | D26: CUENTAS CORRIENTES OPERATIVAS | F26: 6200
A28: A-05 · 10/03/2026 · Por el préstamo desembolsado por el banco | H28: =IF($G$28="SÍ",SUMPRODUCT((($C$29:$C$30="101")+($C$29:$C$30="102")+($C$29:$C$30="1041"))*($E$29:$E$30-$F$29:$F$30)),0)
C29: 1041 | D29: CUENTAS CORRIENTES OPERATIVAS | E29: 15000
C30: 4511 | D30: PRÉSTAMOS DE INSTITUCIONES FINANCIERAS | F30: 15000
A32: A-06 · 25/03/2026 · Por la planilla del mes | H32: =IF($G$32="SÍ",SUMPRODUCT((($C$33:$C$34="101")+($C$33:$C$34="102")+($C$33:$C$34="1041"))*($E$33:$E$34-$F$33:$F$34)),0)
C33: 6211 | D33: SUELDOS Y SALARIOS | E33: 9500
C34: 4111 | D34: SUELDOS Y SALARIOS POR PAGAR | F34: 9500
A36: A-07 · 28/03/2026 · Por el pago de la planilla del mes | H36: =IF($G$36="SÍ",SUMPRODUCT((($C$37:$C$38="101")+($C$37:$C$38="102")+($C$37:$C$38="1041"))*($E$37:$E$38-$F$37:$F$38)),0)
C37: 4111 | D37: SUELDOS Y SALARIOS POR PAGAR | E37: 9500
C38: 1041 | D38: CUENTAS CORRIENTES OPERATIVAS | F38: 9500
A40: A-08 · 29/03/2026 · Por el pago del IGV de febrero a la SUNAT | H40: =IF($G$40="SÍ",SUMPRODUCT((($C$41:$C$42="101")+($C$41:$C$42="102")+($C$41:$C$42="1041"))*($E$41:$E$42-$F$41:$F$42)),0)
C41: 40111 | D41: IGV — CUENTA PROPIA | E41: 3100
C42: 1041 | D42: CUENTAS CORRIENTES OPERATIVAS | F42: 3100
A44: A-09 · 30/03/2026 · Por los intereses del préstamo bancario | H44: =IF($G$44="SÍ",SUMPRODUCT((($C$45:$C$46="101")+($C$45:$C$46="102")+($C$45:$C$46="1041"))*($E$45:$E$46-$F$45:$F$46)),0)
C45: 6731 | D45: PRÉSTAMOS DE INSTITUCIONES FINANCIERAS | E45: 450
C46: 1041 | D46: CUENTAS CORRIENTES OPERATIVAS | F46: 450
A48: A-10 · 31/03/2026 · Por la depreciación del mes | H48: =IF($G$48="SÍ",SUMPRODUCT((($C$49:$C$50="101")+($C$49:$C$50="102")+($C$49:$C$50="1041"))*($E$49:$E$50-$F$49:$F$50)),0)
C49: 68142 | D49: DEPRECIACIÓN DE EQUIPOS DE PROCESAMIENTO | E49: 109.46
C50: 39133 | D50: DEP. ACUM. — EQUIPOS DE PROCESAMIENTO | F50: 109.46
...

Sheet Caso 5 · Flujos
A1: ESTADO DE FLUJOS DE EFECTIVO — COMERCIAL LOS ANDES E.I.R.L.
A2: RUC 20548877231 · Marzo de 2026 · método directo · en soles · se arma solo
B4: Concepto | C4: Importe
A5: FLUJO DE EFECTIVO DE ACTIVIDADES DE OPERACIÓN
B6: Cobranzas a clientes por venta de bienes y servicios | C6: =SUMIF('Caso 5 · Diario'!$I$5:$I$52,$B6,'Caso 5 · Diario'!$H$5:$H$52)
B7: Cobros de regalías, cuotas, comisiones y otros | C7: =SUMIF('Caso 5 · Diario'!$I$5:$I$52,$B7,'Caso 5 · Diario'!$H$5:$H$52)
B8: Pagos a proveedores de bienes y servicios | C8: =SUMIF('Caso 5 · Diario'!$I$5:$I$52,$B8,'Caso 5 · Diario'!$H$5:$H$52)
B9: Pagos de remuneraciones y beneficios sociales | C9: =SUMIF('Caso 5 · Diario'!$I$5:$I$52,$B9,'Caso 5 · Diario'!$H$5:$H$52)
B10: Pago de impuesto a las ganancias | C10: =SUMIF('Caso 5 · Diario'!$I$5:$I$52,$B10,'Caso 5 · Diario'!$H$5:$H$52)
B11: Pago de impuestos — IGV | C11: =SUMIF('Caso 5 · Diario'!$I$5:$I$52,$B11,'Caso 5 · Diario'!$H$5:$H$52)
B12: Otros (pagos) cobros relativos a la actividad, neto | C12: =SUMIF('Caso 5 · Diario'!$I$5:$I$52,$B12,'Caso 5 · Diario'!$H$5:$H$52)
B13: Efectivo neto de las actividades de operación | C13: =SUM($C$6:$C$12)
A14: FLUJO DE EFECTIVO DE ACTIVIDADES DE INVERSIÓN
B15: Cobro por venta de propiedades, planta y equipo | C15: =SUMIF('Caso 5 · Diario'!$I$5:$I$52,$B15,'Caso 5 · Diario'!$H$5:$H$52)
B16: Pagos por compra de propiedades, planta y equipo | C16: =SUMIF('Caso 5 · Diario'!$I$5:$I$52,$B16,'Caso 5 · Diario'!$H$5:$H$52)
B17: Efectivo neto de las actividades de inversión | C17: =SUM($C$15:$C$16)
A18: FLUJO DE EFECTIVO DE ACTIVIDADES DE FINANCIACIÓN
B19: Cobro de préstamos obtenidos | C19: =SUMIF('Caso 5 · Diario'!$I$5:$I$52,$B19,'Caso 5 · Diario'!$H$5:$H$52)
B20: Amortización o pago de préstamos | C20: =SUMIF('Caso 5 · Diario'!$I$5:$I$52,$B20,'Caso 5 · Diario'!$H$5:$H$52)
B21: Intereses pagados | C21: =SUMIF('Caso 5 · Diario'!$I$5:$I$52,$B21,'Caso 5 · Diario'!$H$5:$H$52)
B22: Dividendos pagados | C22: =SUMIF('Caso 5 · Diario'!$I$5:$I$52,$B22,'Caso 5 · Diario'!$H$5:$H$52)
B23: Efectivo neto de las actividades de financiación | C23: =SUM($C$19:$C$22)
B25: AUMENTO (DISMINUCIÓN) NETO DE EFECTIVO Y EQUIVALENTES | C25: =$C$13+$C$17+$C$23
B26: Saldo de efectivo y equivalentes al inicio del mes | C26: 30000
B27: SALDO DE EFECTIVO Y EQUIVALENTES AL FINAL DEL MES | C27: =$C$25+$C$26
A29: =IF(ABS($C$27-52750.00)<0.01,"✓ CUADRA: S/ 52,750.00, igual que el estado de situación financiera.","✗ Todavía no cuadra. Tiene que terminar en S/ 52,750.00 — revisa los asientos sin marcar o mal clasificados.")

Sheet Caso 6 · Situación
A1: ESTADO DE SITUACIÓN FINANCIERA — SERVICIOS YANAHUARA S.A.C.
A2: RUC 20601134908 · Abril de 2026 · en soles
A4: Código | B4: Cuenta | C4: Al cierre | D4: Al inicio
A5: ACTIVO
A6: 101 | B6: Caja | C6: 4250 | D6: 2500
A7: 102 | B7: Fondos fijos | C7: 1500 | D7: 1500
A8: 1041 | B8: Cuentas corrientes operativas | C8: 49500 | D8: 46000
A9: 1212 | B9: Facturas por cobrar — terceros | C9: 0 | D9: 62400
A10: 33411 | B10: Vehículos motorizados — costo | C10: 0 | D10: 42000
A11: 33611 | B11: Equipos de procesamiento de información | C11: 4025.42 | D11: 0
A12: 39 | B12: Depreciación acumulada | C12: -83.86 | D12: -34000
B13: TOTAL ACTIVO | C13: 59191.56 | D13: 120400
A14: PASIVO
A15: 40111 | B15: Tributos por pagar — IGV | C15: 1197.45 | D15: 0
A16: 4017 | B16: Impuesto a la renta por pagar | C16: 0 | D16: 1850
A17: 4212 | B17: Facturas emitidas por pagar — terceros | C17: 0 | D17: 28900
A18: 4511 | B18: Préstamos de instituciones financieras | C18: 0 | D18: 12000
B19: TOTAL PASIVO | C19: 1197.45 | D19: 42750
A20: PATRIMONIO
A21: 5011 | B21: Capital — acciones | C21: 60000 | D21: 60000
A22: 5911 | B22: Resultados acumulados | C22: 9650 | D22: 17650
A23: 59 | B23: Resultado del ejercicio | C23: -11655.89 | D23: 0
B24: TOTAL PATRIMONIO | C24: 57994.11 | D24: 77650
B25: TOTAL PASIVO Y PATRIMONIO | C25: 59191.56 | D25: 120400
B27: EFECTIVO Y EQUIVALENTES DE EFECTIVO | C27: 55250 | D27: 50000
B28: VARIACIÓN DEL EFECTIVO EN EL MES | C28: 5250
A30: Las filas en amarillo son el efectivo. Esa variación de S/ 5,250.00 es la que el estado de flujos tiene que explicar, renglón por renglón.

Sheet Caso 6 · Diario
A1: LIBRO DIARIO — SERVICIOS YANAHUARA S.A.C.
A2: RUC 20601134908 · Abril de 2026 · formato 5.1 · completa las columnas G e I
A4: N° | B4: Fecha | C4: Código | D4: Denominación | E4: Debe | F4: Haber | G4: ¿Mueve efectivo? | H4: Importe del flujo | I4: ¿A qué renglón del flujo va?
A5: B-01 · 01/04/2026 · Por el asiento de apertura | H5: =IF($G$5="SÍ",SUMPRODUCT((($C$6:$C$16="101")+($C$6:$C$16="102")+($C$6:$C$16="1041"))*($E$6:$E$16-$F$6:$F$16)),0)
C6: 101 | D6: CAJA | E6: 2500
C7: 102 | D7: FONDOS FIJOS | E7: 1500
C8: 1041 | D8: CUENTAS CORRIENTES OPERATIVAS | E8: 46000
C9: 1212 | D9: FACTURAS POR COBRAR EMITIDAS EN CARTERA — TERCEROS | E9: 62400
C10: 33411 | D10: VEHÍCULOS MOTORIZADOS — COSTO | E10: 42000
C11: 39131 | D11: DEP. ACUM. — VEHÍCULOS MOTORIZADOS | F11: 34000
C12: 4017 | D12: IMPUESTO A LA RENTA | F12: 1850
C13: 4212 | D13: FACTURAS EMITIDAS POR PAGAR — TERCEROS | F13: 28900
C14: 4511 | D14: PRÉSTAMOS DE INSTITUCIONES FINANCIERAS | F14: 12000
C15: 5011 | D15: ACCIONES | F15: 60000
C16: 5911 | D16: UTILIDADES ACUMULADAS | F16: 17650
A18: B-02 · 04/04/2026 · Por el cobro de las facturas a los clientes | H18: =IF($G$18="SÍ",SUMPRODUCT((($C$19:$C$20="101")+($C$19:$C$20="102")+($C$19:$C$20="1041"))*($E$19:$E$20-$F$19:$F$20)),0)
C19: 1041 | D19: CUENTAS CORRIENTES OPERATIVAS | E19: 62400
C20: 1212 | D20: FACTURAS POR COBRAR EMITIDAS EN CARTERA — TERCEROS | F20: 62400
A22: B-03 · 06/04/2026 · Por el cobro de comisiones del mes en efectivo | H22: =IF($G$22="SÍ",SUMPRODUCT((($C$23:$C$25="101")+($C$23:$C$25="102")+($C$23:$C$25="1041"))*($E$23:$E$25-$F$23:$F$25)),0)
C23: 101 | D23: CAJA | E23: 3600
C24: 40111 | D24: IGV — CUENTA PROPIA | F24: 549.15
C25: 7041 | D25: COMISIONES Y CORRETAJES | F25: 3050.85
A27: B-04 · 08/04/2026 · Por el pago a los proveedores | H27: =IF($G$27="SÍ",SUMPRODUCT((($C$28:$C$29="101")+($C$28:$C$29="102")+($C$28:$C$29="1041"))*($E$28:$E$29-$F$28:$F$29)),0)
C28: 4212 | D28: FACTURAS EMITIDAS POR PAGAR — TERCEROS | E28: 28900
C29: 1041 | D29: CUENTAS CORRIENTES OPERATIVAS | F29: 28900
A31: B-05 · 12/04/2026 · Por la venta al contado de la camioneta | H31: =IF($G$31="SÍ",SUMPRODUCT((($C$32:$C$37="101")+($C$32:$C$37="102")+($C$32:$C$37="1041"))*($E$32:$E$37-$F$32:$F$37)),0)
C32: 1041 | D32: CUENTAS CORRIENTES OPERATIVAS | E32: 9000
C33: 39131 | D33: DEP. ACUM. — VEHÍCULOS MOTORIZADOS | E33: 34000
C34: 6551 | D34: COSTO NETO DE ENAJENACIÓN DE ACTIVOS — IME | E34: 8000
C35: 33411 | D35: VEHÍCULOS MOTORIZADOS — COSTO | F35: 42000
C36: 40111 | D36: IGV — CUENTA PROPIA | F36: 1372.88
C37: 7561 | D37: ENAJENACIÓN DE ACTIVOS INMOVILIZADOS — IME | F37: 7627.12
A39: B-06 · 15/04/2026 · Por la planilla del mes | H39: =IF($G$39="SÍ",SUMPRODUCT((($C$40:$C$41="101")+($C$40:$C$41="102")+($C$40:$C$41="1041"))*($E$40:$E$41-$F$40:$F$41)),0)
C40: 6211 | D40: SUELDOS Y SALARIOS | E40: 14250
C41: 4111 | D41: SUELDOS Y SALARIOS POR PAGAR | F41: 14250
A43: B-07 · 18/04/2026 · Por el pago del impuesto a la renta desde caja | H43: =IF($G$43="SÍ",SUMPRODUCT((($C$44:$C$45="101")+($C$44:$C$45="102")+($C$44:$C$45="1041"))*($E$44:$E$45-$F$44:$F$45)),0)
C44: 4017 | D44: IMPUESTO A LA RENTA | E44: 1850
C45: 101 | D45: CAJA | F45: 1850
A47: B-08 · 20/04/2026 · Por la compra de equipos de cómputo al contado | H47: =IF($G$47="SÍ",SUMPRODUCT((($C$48:$C$50="101")+($C$48:$C$50="102")+($C$48:$C$50="1041"))*($E$48:$E$50-$F$48:$F$50)),0)
C48: 33611 | D48: EQUIPOS DE PROCESAMIENTO DE INFORMACIÓN — COSTO | E48: 4025.42
...

Sheet Caso 6 · Flujos
A1: ESTADO DE FLUJOS DE EFECTIVO — SERVICIOS YANAHUARA S.A.C.
A2: RUC 20601134908 · Abril de 2026 · método directo · en soles · se arma solo
B4: Concepto | C4: Importe
A5: FLUJO DE EFECTIVO DE ACTIVIDADES DE OPERACIÓN
B6: Cobranzas a clientes por venta de bienes y servicios | C6: =SUMIF('Caso 6 · Diario'!$I$5:$I$72,$B6,'Caso 6 · Diario'!$H$5:$H$72)
B7: Cobros de regalías, cuotas, comisiones y otros | C7: =SUMIF('Caso 6 · Diario'!$I$5:$I$72,$B7,'Caso 6 · Diario'!$H$5:$H$72)
B8: Pagos a proveedores de bienes y servicios | C8: =SUMIF('Caso 6 · Diario'!$I$5:$I$72,$B8,'Caso 6 · Diario'!$H$5:$H$72)
B9: Pagos de remuneraciones y beneficios sociales | C9: =SUMIF('Caso 6 · Diario'!$I$5:$I$72,$B9,'Caso 6 · Diario'!$H$5:$H$72)
B10: Pago de impuesto a las ganancias | C10: =SUMIF('Caso 6 · Diario'!$I$5:$I$72,$B10,'Caso 6 · Diario'!$H$5:$H$72)
B11: Pago de impuestos — IGV | C11: =SUMIF('Caso 6 · Diario'!$I$5:$I$72,$B11,'Caso 6 · Diario'!$H$5:$H$72)
B12: Otros (pagos) cobros relativos a la actividad, neto | C12: =SUMIF('Caso 6 · Diario'!$I$5:$I$72,$B12,'Caso 6 · Diario'!$H$5:$H$72)
B13: Efectivo neto de las actividades de operación | C13: =SUM($C$6:$C$12)
A14: FLUJO DE EFECTIVO DE ACTIVIDADES DE INVERSIÓN
B15: Cobro por venta de propiedades, planta y equipo | C15: =SUMIF('Caso 6 · Diario'!$I$5:$I$72,$B15,'Caso 6 · Diario'!$H$5:$H$72)
B16: Pagos por compra de propiedades, planta y equipo | C16: =SUMIF('Caso 6 · Diario'!$I$5:$I$72,$B16,'Caso 6 · Diario'!$H$5:$H$72)
B17: Efectivo neto de las actividades de inversión | C17: =SUM($C$15:$C$16)
A18: FLUJO DE EFECTIVO DE ACTIVIDADES DE FINANCIACIÓN
B19: Cobro de préstamos obtenidos | C19: =SUMIF('Caso 6 · Diario'!$I$5:$I$72,$B19,'Caso 6 · Diario'!$H$5:$H$72)
B20: Amortización o pago de préstamos | C20: =SUMIF('Caso 6 · Diario'!$I$5:$I$72,$B20,'Caso 6 · Diario'!$H$5:$H$72)
B21: Intereses pagados | C21: =SUMIF('Caso 6 · Diario'!$I$5:$I$72,$B21,'Caso 6 · Diario'!$H$5:$H$72)
B22: Dividendos pagados | C22: =SUMIF('Caso 6 · Diario'!$I$5:$I$72,$B22,'Caso 6 · Diario'!$H$5:$H$72)
B23: Efectivo neto de las actividades de financiación | C23: =SUM($C$19:$C$22)
B25: AUMENTO (DISMINUCIÓN) NETO DE EFECTIVO Y EQUIVALENTES | C25: =$C$13+$C$17+$C$23
B26: Saldo de efectivo y equivalentes al inicio del mes | C26: 50000
B27: SALDO DE EFECTIVO Y EQUIVALENTES AL FINAL DEL MES | C27: =$C$25+$C$26
A29: =IF(ABS($C$27-55250.00)<0.01,"✓ CUADRA: S/ 55,250.00, igual que el estado de situación financiera.","✗ Todavía no cuadra. Tiene que terminar en S/ 55,250.00 — revisa los asientos sin marcar o mal clasificados.")

Sheet Listas
A1: Renglones del estado de flujos | C1: Mueve
A2: Cobranzas a clientes por venta de bienes y servicios | C2: SÍ
A3: Cobros de regalías, cuotas, comisiones y otros | C3: NO
A4: Pagos a proveedores de bienes y servicios
A5: Pagos de remuneraciones y beneficios sociales
A6: Pago de impuesto a las ganancias
A7: Pago de impuestos — IGV
A8: Otros (pagos) cobros relativos a la actividad, neto
A9: Cobro por venta de propiedades, planta y equipo
A10: Pagos por compra de propiedades, planta y equipo
A11: Cobro de préstamos obtenidos
A12: Amortización o pago de préstamos
A13: Intereses pagados
A14: Dividendos pagados
