Workbook

Sheet Examen
A1: EXAMEN DE COSTOS - Opcion multiple
A2: Apellidos y nombres:
A3: Fecha: Seccion: | D3: Nota:
A5: INSTRUCCIONES: Cada pregunta tiene una sola respuesta correcta. Escribe la letra (a, b, c o d) en la casilla amarilla "Tu respuesta". Cada pregunta vale 1 punto (total 12).
A7: 1. La panaderia "Dulce Sabor" registra en un lote de produccion: materia prima directa S/ 500, mano de obra directa S/ 300 y costos indirectos de fabricacion S/ 200. Con estos datos, el COSTO PRIMO del lote es:
B8: a) S/ 800
B9: b) S/ 500
B10: c) S/ 1,000
B11: d) S/ 700
B12: Tu respuesta:
A14: 2. Un taller de carpinteria usa en un pedido: materia prima directa S/ 600, mano de obra directa S/ 400 y costos indirectos de fabricacion S/ 350. El COSTO DE CONVERSION del pedido es:
B15: a) S/ 750
B16: b) S/ 1,000
B17: c) S/ 950
B18: d) S/ 1,350
B19: Tu respuesta:
A21: 3. Una fabrica de velas incurre en: materia prima directa S/ 1,200, mano de obra directa S/ 800 y costos indirectos de fabricacion S/ 500. El COSTO DE PRODUCCION es:
B22: a) S/ 2,500
B23: b) S/ 2,000
B24: c) S/ 1,300
B25: d) S/ 1,700
B26: Tu respuesta:
A28: 4. En un mes se producen 100 sillas con: materia prima directa S/ 1,000, mano de obra directa S/ 500 y costos indirectos de fabricacion S/ 500. El COSTO UNITARIO DE PRODUCCION de cada silla es:
B29: a) S/ 20
B30: b) S/ 15
B31: c) S/ 10
B32: d) S/ 2,000
B33: Tu respuesta:
A35: 5. El costo variable unitario de una botella de gaseosa es S/ 3. Si en el dia se producen 500 botellas, el COSTO VARIABLE TOTAL es:
B36: a) S/ 1,500
B37: b) S/ 500
B38: c) S/ 3,000
B39: d) S/ 167
B40: Tu respuesta:
A42: 6. Producir 200 empanadas tuvo un costo variable total de S/ 600. El COSTO VARIABLE UNITARIO de cada empanada es:
B43: a) S/ 3
B44: b) S/ 6
B45: c) S/ 0.33
B46: d) S/ 800
B47: Tu respuesta:
...

Sheet Calificacion
A1: CALIFICACION AUTOMATICA
A2: Se completa sola cuando el alumno llena las casillas amarillas de la hoja "Examen".
A4: Pregunta | B4: Tu respuesta | C4: Resultado | D4: Puntos
A5: Pregunta 1 | B5: =IF(Examen!C12="","-",UPPER(Examen!C12)) -> - | C5: =IF(Examen!C12="","Sin responder",IF(UPPER(TRIM(Examen!C12))=UPPER(Clave!B5),"Correcto","Incorrecto")) -> Sin responder | D5: =IF(UPPER(TRIM(Examen!C12))=UPPER(Clave!B5),1,0) -> 0
A6: Pregunta 2 | B6: =IF(Examen!C19="","-",UPPER(Examen!C19)) -> - | C6: =IF(Examen!C19="","Sin responder",IF(UPPER(TRIM(Examen!C19))=UPPER(Clave!B6),"Correcto","Incorrecto")) -> Sin responder | D6: =IF(UPPER(TRIM(Examen!C19))=UPPER(Clave!B6),1,0) -> 0
A7: Pregunta 3 | B7: =IF(Examen!C26="","-",UPPER(Examen!C26)) -> - | C7: =IF(Examen!C26="","Sin responder",IF(UPPER(TRIM(Examen!C26))=UPPER(Clave!B7),"Correcto","Incorrecto")) -> Sin responder | D7: =IF(UPPER(TRIM(Examen!C26))=UPPER(Clave!B7),1,0) -> 0
A8: Pregunta 4 | B8: =IF(Examen!C33="","-",UPPER(Examen!C33)) -> - | C8: =IF(Examen!C33="","Sin responder",IF(UPPER(TRIM(Examen!C33))=UPPER(Clave!B8),"Correcto","Incorrecto")) -> Sin responder | D8: =IF(UPPER(TRIM(Examen!C33))=UPPER(Clave!B8),1,0) -> 0
A9: Pregunta 5 | B9: =IF(Examen!C40="","-",UPPER(Examen!C40)) -> - | C9: =IF(Examen!C40="","Sin responder",IF(UPPER(TRIM(Examen!C40))=UPPER(Clave!B9),"Correcto","Incorrecto")) -> Sin responder | D9: =IF(UPPER(TRIM(Examen!C40))=UPPER(Clave!B9),1,0) -> 0
A10: Pregunta 6 | B10: =IF(Examen!C47="","-",UPPER(Examen!C47)) -> - | C10: =IF(Examen!C47="","Sin responder",IF(UPPER(TRIM(Examen!C47))=UPPER(Clave!B10),"Correcto","Incorrecto")) -> Sin responder | D10: =IF(UPPER(TRIM(Examen!C47))=UPPER(Clave!B10),1,0) -> 0
A11: Pregunta 7 | B11: =IF(Examen!C54="","-",UPPER(Examen!C54)) -> - | C11: =IF(Examen!C54="","Sin responder",IF(UPPER(TRIM(Examen!C54))=UPPER(Clave!B11),"Correcto","Incorrecto")) -> Sin responder | D11: =IF(UPPER(TRIM(Examen!C54))=UPPER(Clave!B11),1,0) -> 0
A12: Pregunta 8 | B12: =IF(Examen!C61="","-",UPPER(Examen!C61)) -> - | C12: =IF(Examen!C61="","Sin responder",IF(UPPER(TRIM(Examen!C61))=UPPER(Clave!B12),"Correcto","Incorrecto")) -> Sin responder | D12: =IF(UPPER(TRIM(Examen!C61))=UPPER(Clave!B12),1,0) -> 0
A13: Pregunta 9 | B13: =IF(Examen!C68="","-",UPPER(Examen!C68)) -> - | C13: =IF(Examen!C68="","Sin responder",IF(UPPER(TRIM(Examen!C68))=UPPER(Clave!B13),"Correcto","Incorrecto")) -> Sin responder | D13: =IF(UPPER(TRIM(Examen!C68))=UPPER(Clave!B13),1,0) -> 0
A14: Pregunta 10 | B14: =IF(Examen!C75="","-",UPPER(Examen!C75)) -> - | C14: =IF(Examen!C75="","Sin responder",IF(UPPER(TRIM(Examen!C75))=UPPER(Clave!B14),"Correcto","Incorrecto")) -> Sin responder | D14: =IF(UPPER(TRIM(Examen!C75))=UPPER(Clave!B14),1,0) -> 0
A15: Pregunta 11 | B15: =IF(Examen!C82="","-",UPPER(Examen!C82)) -> - | C15: =IF(Examen!C82="","Sin responder",IF(UPPER(TRIM(Examen!C82))=UPPER(Clave!B15),"Correcto","Incorrecto")) -> Sin responder | D15: =IF(UPPER(TRIM(Examen!C82))=UPPER(Clave!B15),1,0) -> 0
A16: Pregunta 12 | B16: =IF(Examen!C89="","-",UPPER(Examen!C89)) -> - | C16: =IF(Examen!C89="","Sin responder",IF(UPPER(TRIM(Examen!C89))=UPPER(Clave!B16),"Correcto","Incorrecto")) -> Sin responder | D16: =IF(UPPER(TRIM(Examen!C89))=UPPER(Clave!B16),1,0) -> 0
A17: PUNTAJE TOTAL | D17: =SUM(D5:D16) -> 0
A18: PORCENTAJE DE ACIERTO | D18: =D17/12 -> 0
A19: NOTA VIGESIMAL (0-20) | D19: =ROUND(D17/12*20,0) -> 0

Sheet Clave
A1: CLAVE DE RESPUESTAS Y EXPLICACIONES (uso del docente)
A2: Sugerencia: oculta o elimina esta hoja antes de entregar el archivo a los alumnos.
A4: Pregunta | B4: Correcta | C4: Respuesta correcta | D4: Por que (formula aplicada)
A5: Pregunta 1 | B5: A | C5: S/ 800 | D5: Costo primo = parte directa = MPD + MOD = 500 + 300 = S/ 800. El CIF no entra en el costo primo.
A6: Pregunta 2 | B6: A | C6: S/ 750 | D6: Conversion = lo que cuesta transformar la MP = MOD + CIF = 400 + 350 = S/ 750. La MPD no entra en la conversion.
A7: Pregunta 3 | B7: A | C7: S/ 2,500 | D7: Costo de produccion = MPD + MOD + CIF = 1,200 + 800 + 500 = S/ 2,500.
A8: Pregunta 4 | B8: A | C8: S/ 20 | D8: Primero el costo de produccion = 1,000 + 500 + 500 = 2,000. Luego CU = 2,000 / 100 unidades = S/ 20.
A9: Pregunta 5 | B9: A | C9: S/ 1,500 | D9: Costo variable total = CVU x Q = 3 x 500 = S/ 1,500. Crece en proporcion al volumen.
A10: Pregunta 6 | B10: A | C10: S/ 3 | D10: Costo variable unitario = CV / Q = 600 / 200 = S/ 3. Se mantiene constante por unidad.
A11: Pregunta 7 | B11: A | C11: S/ 12 y S/ 9 | D11: CFU = CF / Q. Con 300: 3,600/300 = S/ 12; con 400: 3,600/400 = S/ 9. El costo fijo unitario BAJA cuando sube el volumen.
A12: Pregunta 8 | B12: A | C12: S/ 3,500 | D12: Costo total = CF + CVU x Q = 2,000 + (5 x 300) = 2,000 + 1,500 = S/ 3,500.
A13: Pregunta 9 | B13: A | C13: S/ 14 | D13: Primero el costo fijo unitario = 3,000/500 = 6. Costo unitario total = CVU + CFU = 8 + 6 = S/ 14.
A14: Pregunta 10 | B14: A | C14: S/ 60 | D14: Costo unitario = 2,000/50 = 40. Precio = CU x (1 + r) = 40 x 1.50 = S/ 60.
A15: Pregunta 11 | B15: A | C15: 33.33% | D15: Margen bruto = (Precio - CU) / Precio = (60 - 40)/60 = 20/60 = 33.33%. Ojo: se calcula SOBRE el precio, no sobre el costo.
A16: Pregunta 12 | B16: A | C16: S/ 50 | D16: Cuando se fija primero el margen: Precio = CU / (1 - m) = 30 / (1 - 0.40) = 30 / 0.60 = S/ 50.
